Workbook

Sheet Modification MORA & R&R Jan2024
E1: 45292 | F1: 45261
D2: USD | E2: 4.7295 | F2: 4.59 | I2: Impaired
D3: EUR | E3: 5.1173 | F3: 5.0768
D4: RM | E4: 1 | F4: 1
B5: 2020 | N5: Using initial rate
B6: No. | C6: Borrower code | D6: GL Code | E6: Borrower | F6: Trade/Non trade | G6: Currency | H6: SME/ NON SME | I6: Status based on AFS FY2020 | J6: Islamic/ conventional | K6: SLO acceptance date | L6: Auto Mora/Mora/Non-auto mora (R&R) | M6: Modification impact (Original Currency) | N6: Amortisation in Jan 2024 | O6: Revised Modification impact (Original Currency) | P6: Fx | Q6: Modification impact (RM) | U6: Initial rate
B7: 1 | C7: 500749 | D7: 134003 | E7: Istanbul Sabiha Gocken | F7: Non trade | G7: EUR | H7: Non SME | I7: =VLOOKUP(C7,[1]Sheet1!$B$1:$M$34,12,FALSE) -> R&R | J7: Conventional | K7: 44161 | L7: Non Auto Mora | M7: 17452.936 | N7: -935.86 | O7: =SUM(M7:N7) -> 16517.076 | P7: =SUMIF($D$2:$D$4,G7,$E$2:$E$4) -> 5.1173 | Q7: =O7*P7 -> 84522.832 | U7: 4.94130
B8: 2 | C8: 500931 | D8: 2230005 | E8: Lipidchem 2 | F8: Non trade | G8: RM | H8: SME | I8: Mora | J8: Islamic | K8: 44104 | L8: Auto Mora | M8: -2916.5081 | N8: -4030.72 | O8: =SUM(M8:N8) -> -6947.2281 | P8: =SUMIF($D$2:$D$4,G8,$E$2:$E$4) -> 1 | Q8: =O8*P8 -> -6947.2281 | U8: 1
G9: RM | M9: =SUMIF($G$7:$G$8,G9,$M$7:$M$8) -> -2916.5081 | N9: =SUMIF($G$7:$G$8,G9,$N$7:$N$8) -> -4030.72 | O9: =SUMIF($G$7:$G$8,G9,$O$7:$O$8) -> -6947.2281 | Q9: =SUM(Q7:Q8) -> 77575.604
G10: USD | M10: =SUMIF($G$7:$G$8,G10,$M$7:$M$8) -> 0 | N10: =SUMIF($G$7:$G$8,G10,$N$7:$N$8) -> 0 | O10: =SUMIF($G$7:$G$8,G10,$O$7:$O$8) -> 0
G11: EUR | M11: =SUMIF($G$7:$G$8,G11,$M$7:$M$8) -> 17452.936 | N11: =SUMIF($G$7:$G$8,G11,$N$7:$N$8) -> -935.86 | O11: =SUMIF($G$7:$G$8,G11,$O$7:$O$8) -> 16517.076
B13: 2021
B14: No. | C14: Borrower code | D14: GL Code | E14: Borrower | F14: Trade/Non trade | G14: Currency | H14: SME/NON SME | J14: Islamic/ conventional | K14: SLO acceptance date | L14: Auto Mora/Mora/Non-auto mora (R&R) | M14: Modification impact (Original Currency) | N14: Amortisation in Jan 2024 | O14: Revised Modification impact (Original Currency) | P14: Fx | Q14: Modification impact (RM)
B15: 1 | C15: 500642 | D15: 134003 | E15: OM Materials (Sarawak) Sdn Bhd (Tranche A1) Facility A | F15: Non trade | G15: USD | H15: Non SME | J15: Conventional | K15: 44322 | L15: R&R | M15: 24038.029 | N15: -700.73 | O15: =SUM(M15:N15) -> 23337.299 | P15: =SUMIF($D$2:$D$4,G15,$E$2:$E$4) -> 4.7295 | Q15: =O15*P15 -> 110373.76 | U15: 4.21100
B16: 2 | C16: 500640 | D16: 134003 | E16: OM Materials (Sarawak) Sdn Bhd (Tranche B) Facility C | F16: Non trade | G16: USD | H16: Non SME | J16: Conventional | K16: 44322 | L16: R&R | M16: 37387.239 | N16: -1059.6 | O16: =SUM(M16:N16) -> 36327.639 | P16: =SUMIF($D$2:$D$4,G16,$E$2:$E$4) -> 4.7295 | Q16: =O16*P16 -> 171811.57 | U16: 4.21100
B17: 3 | C17: 501030 | D17: 2230005 | E17: SSP Raw Metals Trading Sdn Bhd | F17: Non trade | G17: RM | H17: SME | J17: Islamic | K17: 44460 | L17: PEMULIH | M17: 574.1313 | N17: -164.25 | O17: =SUM(M17:N17) -> 409.8813 | P17: =SUMIF($D$2:$D$4,G17,$E$2:$E$4) -> 1 | Q17: =O17*P17 -> 409.8813 | U17: 1
Q18: =SUM(Q15:Q17) -> 282595.2
G19: RM | M19: =SUMIF($G$15:$G$17,G19,$M$15:$M$17) -> 574.1313 | N19: =SUMIF($G$15:$G$17,G19,$N$15:$N$17) -> -164.25 | O19: =SUMIF($G$15:$G$17,G19,$O$15:$O$17) -> 409.8813
G20: USD | M20: =SUMIF($G$15:$G$17,G20,$M$15:$M$17) -> 61425.268 | N20: =SUMIF($G$15:$G$17,G20,$N$15:$N$17) -> -1760.33 | O20: =SUMIF($G$15:$G$17,G20,$O$15:$O$17) -> 59664.938
B23: 2022
B24: No. | C24: Borrower code | D24: GL Code | E24: Borrower | F24: Trade/ Non trade | G24: Currency | H24: SME/NON SME | J24: Islamic/ conventional | K24: SLO acceptance date | L24: Auto Mora/Mora/Non-auto mora (R&R) | M24: Modification impact (Original Currency) | N24: Amortisation in Jan 2024 | O24: Revised Modification impact (Original Currency) | P24: Fx | Q24: Modification impact (RM)
B25: 1 | C25: 500860 | D25: 2230005 | E25: Lantana Services Sdn Bhd | F25: Non trade | G25: RM | H25: SME | J25: Islamic | K25: 44704 | L25: R&R | M25: 318.64742 | N25: -150.87 | O25: =SUM(M25:N25) -> 167.77742 | P25: =SUMIF($D$2:$D$4,G25,$E$2:$E$4) -> 1 | Q25: =O25*P25 -> 167.77742 | U25: 1
B26: 2 | C26: 501010 | D26: 2230005 | E26: Malaysian Phosphate Additives (Sarawak) Sdn Bhd | F26: Non trade | G26: USD | H26: Non SME | J26: Islamic | K26: 44831 | L26: R&R | M26: 22266.865 | N26: -2130.29 | O26: =SUM(M26:N26) -> 20136.575 | P26: =SUMIF($D$2:$D$4,G26,$E$2:$E$4) -> 4.7295 | Q26: =O26*P26 -> 95235.931 | U26: 4.728
Q27: =SUBTOTAL(9,Q25:Q26) -> 95403.708
G28: RM | M28: =SUMIF($G$25:$G$26,G28,$M$25:$M$26) -> 318.64742 | N28: =SUMIF($G$25:$G$26,G28,$N$25:$N$26) -> -150.87 | O28: =SUMIF($G$25:$G$26,G28,$O$25:$O$26) -> 167.77742
G29: USD | M29: =SUMIF($G$25:$G$26,G29,$M$25:$M$26) -> 22266.865 | N29: =SUMIF($G$25:$G$26,G29,$N$25:$N$26) -> -2130.29 | O29: =SUMIF($G$25:$G$26,G29,$O$25:$O$26) -> 20136.575
B32: 2023
B33: No. | C33: Borrower code | D33: GL Code | E33: Borrower | F33: Trade/ Non trade | G33: Currency | H33: SME/NON SME | J33: Islamic/ conventional | K33: SLO acceptance date | L33: Auto Mora/Mora/Non-auto mora (R&R) | M33: Modification impact (Original Currency) | N33: Amortisation in Jan 2024 | O33: Revised Modification impact (Original Currency) | P33: Fx | Q33: Modification impact (RM)
B34: 1 | C34: 500941 | D34: 2230005 | E34: PWN Excellence Sdn Bhd 1 | F34: Non trade | G34: RM | H34: SME | J34: Islamic | K34: 45149 | L34: R&R | M34: -553612.81 | N34: 58307.99 | O34: =SUM(M34:N34) -> -495304.82 | P34: =SUMIF($D$2:$D$4,G34,$E$2:$E$4) -> 1 | Q34: =O34*P34 -> -495304.82 | U34: 1
B35: 2 | C35: 500943 | D35: 2230005 | E35: PWN Excellence Sdn Bhd 3 | F35: Non trade | G35: RM | H35: SME | J35: Islamic | K35: 45149 | L35: R&R | M35: -53001.579 | N35: 4369.71 | O35: =SUM(M35:N35) -> -48631.869 | P35: =SUMIF($D$2:$D$4,G35,$E$2:$E$4) -> 1 | Q35: =O35*P35 -> -48631.869 | U35: 1
Q36: =SUBTOTAL(9,Q34:Q35) -> -543936.69
G37: RM | M37: =SUMIF($G$34:$G$35,G37,$M$34:$M$35) -> -606614.39 | N37: =SUMIF($G$34:$G$35,G37,$N$34:$N$35) -> 62677.7 | O37: =SUMIF($G$34:$G$35,G37,$O$34:$O$35) -> -543936.69
G38: USD | M38: =SUMIF($G$34:$G$35,G38,$M$34:$M$35) -> 0 | N38: =SUMIF($G$34:$G$35,G38,$N$34:$N$35) -> 0 | O38: =SUMIF($G$34:$G$35,G38,$O$34:$O$35) -> 0
G40: TOTAL | Q40: =Q9+Q18+Q27+Q36 -> -88362.172
Q42: As per listing | R42: SAP | S42: Variance
O43: 134003 | P43: Conventional | Q43: =SUMIF($J$6:$J$35,P43,$Q$6:$Q$35) -> 366708.15 | S43: =Q43-R43 -> 366708.15
O44: 2230005 | P44: Islamic | Q44: =SUMIF($J$6:$J$35,P44,$Q$6:$Q$35) -> -455070.33 | S44: =Q44-R44 -> -455070.33
P45: Total | Q45: =SUM(Q43:Q44) -> -88362.172 | R45: =SUM(R43:R44) -> 0 | S45: =SUM(S43:S44) -> -88362.172

Sheet Modification MORA & R&R May2024
E1: 45413 | F1: 45383
D2: USD | E2: 4.707 | F2: 4.77 | I2: Impaired
D3: EUR | E3: 5.1 | F3: 5.1096
D4: RM | E4: 1 | F4: 1
B5: 2020 | N5: Using initial rate
B6: No. | C6: Borrower code | D6: GL Code | E6: Borrower | F6: Trade/Non trade | G6: Currency | H6: SME/ NON SME | I6: Status based on AFS FY2020 | J6: Islamic/ conventional | K6: SLO acceptance date | L6: Auto Mora/Mora/Non-auto mora (R&R) | M6: Modification impact (Original Currency) | N6: Amortisation in May 2024 | O6: Revised Modification impact (Original Currency) | P6: Fx | Q6: Modification impact (RM) | U6: Initial rate
B7: 1 | C7: 500749 | D7: 134003 | E7: Istanbul Sabiha Gocken | F7: Non trade | G7: EUR | H7: Non SME | I7: =VLOOKUP(C7,[1]Sheet1!$B$1:$M$34,12,FALSE) -> R&R | J7: Conventional | K7: 44161 | L7: Non Auto Mora | M7: 13709.496 | N7: -935.86 | O7: =SUM(M7:N7) -> 12773.636 | P7: =SUMIF($D$2:$D$4,G7,$E$2:$E$4) -> 5.1 | Q7: =O7*P7 -> 65145.543 | U7: 4.94130
B8: 2 | C8: 500931 | D8: 2230005 | E8: Lipidchem 2 | F8: Non trade | G8: RM | H8: SME | I8: Mora | J8: Islamic | K8: 44104 | L8: Auto Mora | M8: -16921.728 | N8: -3050.1707 | O8: =SUM(M8:N8) -> -19971.899 | P8: =SUMIF($D$2:$D$4,G8,$E$2:$E$4) -> 1 | Q8: =O8*P8 -> -19971.899 | U8: 1
G9: RM | M9: =SUMIF($G$7:$G$8,G9,$M$7:$M$8) -> -16921.728 | N9: =SUMIF($G$7:$G$8,G9,$N$7:$N$8) -> -3050.1707 | O9: =SUMIF($G$7:$G$8,G9,$O$7:$O$8) -> -19971.899 | Q9: =SUM(Q7:Q8) -> 45173.644
G10: USD | M10: =SUMIF($G$7:$G$8,G10,$M$7:$M$8) -> 0 | N10: =SUMIF($G$7:$G$8,G10,$N$7:$N$8) -> 0 | O10: =SUMIF($G$7:$G$8,G10,$O$7:$O$8) -> 0
G11: EUR | M11: =SUMIF($G$7:$G$8,G11,$M$7:$M$8) -> 13709.496 | N11: =SUMIF($G$7:$G$8,G11,$N$7:$N$8) -> -935.86 | O11: =SUMIF($G$7:$G$8,G11,$O$7:$O$8) -> 12773.636
B13: 2021
B14: No. | C14: Borrower code | D14: GL Code | E14: Borrower | F14: Trade/Non trade | G14: Currency | H14: SME/NON SME | J14: Islamic/ conventional | K14: SLO acceptance date | L14: Auto Mora/Mora/Non-auto mora (R&R) | M14: Modification impact (Original Currency) | N14: Amortisation in May 2024 | O14: Revised Modification impact (Original Currency) | P14: Fx | Q14: Modification impact (RM)
B15: 1 | C15: 500642 | D15: 134003 | E15: OM Materials (Sarawak) Sdn Bhd (Tranche A1) Facility A | F15: Non trade | G15: USD | H15: Non SME | J15: Conventional | K15: 44322 | L15: R&R | M15: 21268.409 | N15: -667.43 | O15: =SUM(M15:N15) -> 20600.979 | P15: =SUMIF($D$2:$D$4,G15,$E$2:$E$4) -> 4.707 | Q15: =O15*P15 -> 96968.808 | U15: 4.21100
B16: 2 | C16: 500640 | D16: 134003 | E16: OM Materials (Sarawak) Sdn Bhd (Tranche B) Facility C | F16: Non trade | G16: USD | H16: Non SME | J16: Conventional | K16: 44322 | L16: R&R | M16: 33196.259 | N16: -1012.18 | O16: =SUM(M16:N16) -> 32184.079 | P16: =SUMIF($D$2:$D$4,G16,$E$2:$E$4) -> 4.707 | Q16: =O16*P16 -> 151490.46 | U16: 4.21100
Q17: =SUM(Q15:Q16) -> 248459.27
G18: RM | M18: =SUMIF($G$15:$G$16,G18,$M$15:$M$16) -> 0 | N18: =SUMIF($G$15:$G$16,G18,$N$15:$N$16) -> 0 | O18: =SUMIF($G$15:$G$16,G18,$O$15:$O$16) -> 0
G19: USD | M19: =SUMIF($G$15:$G$16,G19,$M$15:$M$16) -> 54464.668 | N19: =SUMIF($G$15:$G$16,G19,$N$15:$N$16) -> -1679.61 | O19: =SUMIF($G$15:$G$16,G19,$O$15:$O$16) -> 52785.058
B22: 2022
B23: No. | C23: Borrower code | D23: GL Code | E23: Borrower | F23: Trade/ Non trade | G23: Currency | H23: SME/NON SME | J23: Islamic/ conventional | K23: SLO acceptance date | L23: Auto Mora/Mora/Non-auto mora (R&R) | M23: Modification impact (Original Currency) | N23: Amortisation in May 2024 | O23: Revised Modification impact (Original Currency) | P23: Fx | Q23: Modification impact (RM)
B24: 1 | C24: 501010 | D24: 2230005 | E24: Malaysian Phosphate Additives (Sarawak) Sdn Bhd | F24: Non trade | G24: USD | H24: Non SME | J24: Islamic | K24: 44831 | L24: R&R | M24: 18295.555 | N24: 97.88 | O24: =SUM(M24:N24) -> 18393.435 | P24: =SUMIF($D$2:$D$4,G24,$E$2:$E$4) -> 4.707 | Q24: =O24*P24 -> 86577.898 | U24: 4.728
Q25: =SUBTOTAL(9,Q24:Q24) -> 86577.898
G26: RM | M26: =SUMIF($G$24:$G$24,G26,$M$24:$M$24) -> 0 | N26: =SUMIF($G$24:$G$24,G26,$N$24:$N$24) -> 0 | O26: =SUMIF($G$24:$G$24,G26,$O$24:$O$24) -> 0
G27: USD | M27: =SUMIF($G$24:$G$24,G27,$M$24:$M$24) -> 18295.555 | N27: =SUMIF($G$24:$G$24,G27,$N$24:$N$24) -> 97.88 | O27: =SUMIF($G$24:$G$24,G27,$O$24:$O$24) -> 18393.435
B30: 2023
B31: No. | C31: Borrower code | D31: GL Code | E31: Borrower | F31: Trade/ Non trade | G31: Currency | H31: SME/NON SME | J31: Islamic/ conventional | K31: SLO acceptance date | L31: Auto Mora/Mora/Non-auto mora (R&R) | M31: Modification impact (Original Currency) | N31: Amortisation in May 2024 | O31: Revised Modification impact (Original Currency) | P31: Fx | Q31: Modification impact (RM)
B32: 1 | C32: 500941 | D32: 2230005 | E32: PWN Excellence Sdn Bhd 1 | F32: Non trade | G32: RM | H32: SME | J32: Islamic | K32: 45149 | L32: R&R | M32: -310645.62 | N32: 63939.96 | O32: =SUM(M32:N32) -> -246705.66 | P32: =SUMIF($D$2:$D$4,G32,$E$2:$E$4) -> 1 | Q32: =O32*P32 -> -246705.66 | U32: 1
B33: 2 | C33: 500943 | D33: 2230005 | E33: PWN Excellence Sdn Bhd 3 | F33: Non trade | G33: RM | H33: SME | J33: Islamic | K33: 45149 | L33: R&R | M33: -29547.009 | N33: 7407.43 | O33: =SUM(M33:N33) -> -22139.579 | P33: =SUMIF($D$2:$D$4,G33,$E$2:$E$4) -> 1 | Q33: =O33*P33 -> -22139.579 | U33: 1
Q34: =SUBTOTAL(9,Q32:Q33) -> -268845.24
G35: RM | M35: =SUMIF($G$32:$G$33,G35,$M$32:$M$33) -> -340192.63 | N35: =SUMIF($G$32:$G$33,G35,$N$32:$N$33) -> 71347.39 | O35: =SUMIF($G$32:$G$33,G35,$O$32:$O$33) -> -268845.24
G36: USD | M36: =SUMIF($G$32:$G$33,G36,$M$32:$M$33) -> 0 | N36: =SUMIF($G$32:$G$33,G36,$N$32:$N$33) -> 0 | O36: =SUMIF($G$32:$G$33,G36,$O$32:$O$33) -> 0
G38: TOTAL | Q38: =Q9+Q17+Q25+Q34 -> 111365.57
Q40: As per listing | R40: SAP | S40: Variance
O41: 134003 | P41: Conventional | Q41: =SUMIF($J$6:$J$33,P41,$Q$6:$Q$33) -> 313604.81 | S41: =Q41-R41 -> 313604.81
O42: 2230005 | P42: Islamic | Q42: =SUMIF($J$6:$J$33,P42,$Q$6:$Q$33) -> -202239.24 | S42: =Q42-R42 -> -202239.24
P43: Total | Q43: =SUM(Q41:Q42) -> 111365.57 | R43: =SUM(R41:R42) -> 0 | S43: =SUM(S41:S42) -> 111365.57

Sheet Debtors Listing Islamic (Cost)
A1: Cost Outstanding (MYR) for Islamic Financing as at 31st July 2026 | U1: USD | V1: 4.081 | W1: EUR | X1: 4.7017 | Y1: SGD | Z1: 3.1854
U2: GBP | V2: 5.4924 | W2: AUD | X2: 2.8734
A6: No. | B6: Company | C6: Customer Account | D6: Currency | E6: Remarks | G6: Opening | H6: Disbursement | I6: Adjustment/ Capitalisation | J6: Forex (+) | K6: Unearned | L6: Rental (Ijarah) | M6: Cost Payment | N6: Profit | O6: Adjustment/ Capitalisation | P6: Forex (-) | Q6: Unearned | R6: Balance | T6: Base Currency COD & ARRD | V6: COD & ARRD in Local Currency
K7: Profit | N7: Payment | Q7: Profit
B8: Islamic Financing Facility
B10: Supplier Credit Islamic Financing Facility & Letter of Credit/Trust Receipt
B11: Allied PT Resources Sdn Bhd | C11: 500685 | D11: MYR | G11: 3.6789061e-10 | R11: =G11+H11+J11+K11+I11-M11-O11-P11-Q11-N11 -> 3.6789061e-10
B12: Arab Malaysian Vegetable Oil Products Co Ltd | C12: 500548 | D12: USD | G12: 8.4401108e-09 | R12: =G12+H12+J12+K12+I12-M12-O12-P12-Q12-N12 -> 8.4401108e-09
B13: Arab Malaysian Vegetable Oil Products Co Ltd - Trade | C13: 500556 | D13: USD | G13: 5.1455572e-08 | R13: =G13+H13+J13+K13+I13-M13-O13-P13-Q13-N13 -> 5.1455572e-08
B14: Awin Resources (Malaysia) Ltd | C14: 500858 | D14: USD | G14: -1.3643876e-07 | R14: =G14+H14+J14+K14+I14-M14-O14-P14-Q14-N14 -> -1.3643876e-07
B15: Destini Prima Sdn Bhd | C15: 500731 | D15: USD | G15: -0.0029999966 | R15: =G15+H15+J15+K15+I15-M15-O15-P15-Q15-N15 -> -0.0029999966
B16: Central Sugar Refinery | C16: 500815 | D16: MYR | G16: 1.2805685e-08 | R16: =G16+H16+J16+K16+I16-M16-O16-P16-Q16-N16 -> 1.2805685e-08
B17: Continental Resources Sdn Bhd | C17: 500813 | D17: USD | G17: -3.4749974e-08 | R17: =G17+H17+J17+K17+I17-M17-O17-P17-Q17-N17 -> -3.4749974e-08
B18: EON Metal Technology Sdn Bhd | C18: 500830 | D18: USD | G18: 4.3655746e-10 | R18: =G18+H18+J18+K18+I18-M18-O18-P18-Q18-N18 -> 4.3655746e-10
B19: Destini Shipbuilding & Engineering | C19: 500908 | D19: EUR | G19: 3.9581209e-09 | R19: =G19+H19+J19+K19+I19-M19-O19-P19-Q19-N19 -> 3.9581209e-09
A20: 1 | B20: Envico Enterprise Sdn Bhd | C20: 500968 | D20: USD | E20: Monthly Financial Cost Sep20 - Dec20 | G20: -0.0013749599 | R20: =F20+G20+H20+J20+K20+I20-M20-O20-P20-Q20-N20 -> -0.0013749599 | S20: =R20-V20 -> -0.0013749599 | V20: =T20*$V$1 -> 0 | AC20: =G20+H20+I20+J20-M20-O20-P20 -> -0.0013749599
A21: 1 | B21: Aescomed Healthcare Sdn Bhd | C21: 501125 | D21: MYR | G21: -1.7462298e-10 | R21: =G21+H21+J21+K21+I21-M21-O21-P21-Q21-N21 -> -1.7462298e-10 | S21: =R21-V21 -> -1.7462298e-10 | U21: =D21 -> MYR | V21: =T21 -> 0
A22: 1 | B22: ACE Champion Sdn Bhd | C22: 501285 | D22: MYR | G22: 4579063.4 | H22: 1237439.1 | M22: 965682.83 | R22: =G22+H22+J22+K22+I22-M22-O22-P22-Q22-N22 -> 4850819.7 | S22: =R22-V22 -> 0 | T22: 4850819.7 | U22: =D22 -> MYR | V22: =T22 -> 4850819.7
A23: 2 | B23: Agro 19 Berhad | C23: 501111 | D23: MYR | G23: 9976471.3 | M23: 4092610.8 | R23: =G23+H23+J23+K23+I23-M23-O23-P23-Q23-N23 -> 5883860.4 | S23: =R23-V23 -> 0 | T23: 5883860.5 | U23: =D23 -> MYR | V23: =T23 -> 5883860.5 | AB23: =H23+I23-M23-O23 -> -4092610.8
A24: 3 | B24: Agro 19 Berhad 2 | C24: 501172 | D24: MYR | G24: 29997745 | H24: 17561516 | M24: 19344759 | R24: =G24+H24+J24+K24+I24-M24-O24-P24-Q24-N24 -> 28214502 | S24: =R24-V24 -> 0 | T24: 28214502 | U24: =D24 -> MYR | V24: =T24 -> 28214502
A25: 4 | B25: Agro 19 Berhad 3 | C25: 501291 | D25: MYR | G25: 39822432 | M25: 817900.6 | R25: =G25+H25+J25+K25+I25-M25-O25-P25-Q25-N25 -> 39004531 | S25: =R25-V25 -> 0 | T25: 39004531 | U25: =D25 -> MYR | V25: =T25 -> 39004531
A26: 5 | B26: Agro 19 Berhad 4 | C26: 501350 | D26: MYR | G26: 5000000 | R26: =G26+H26+J26+K26+I26-M26-O26-P26-Q26-N26 -> 5000000 | S26: =R26-V26 -> 0 | T26: 5000000 | U26: =D26 -> MYR | V26: =T26 -> 5000000
A27: 6 | B27: Agro 19 Berhad - RCi | C27: 501356 | D27: MYR | H27: 1357851.1 | R27: =G27+H27+J27+K27+I27-M27-O27-P27-Q27-N27 -> 1357851.1 | S27: =R27-V27 -> 0 | T27: 1357851.1 | U27: =D27 -> MYR | V27: =T27 -> 1357851.1
A28: 7 | B28: AMC Cincaria Sdn Bhd | C28: 501129 | D28: MYR | G28: 3666201.7 | H28: 2026179.2 | M28: 1530367.5 | R28: =G28+H28+J28+K28+I28-M28-O28-P28-Q28-N28 -> 4162013.4 | S28: =R28-V28 -> 0 | T28: 4162013.4 | U28: =D28 -> MYR | V28: =T28 -> 4162013.4
A29: 6 | B29: Ann Joo Integrated Steel Sdn Bhd | C29: 501161 | D29: MYR | G29: 8.7311491e-09 | R29: =G29+H29+J29+K29+I29-M29-O29-P29-Q29-N29 -> 8.7311491e-09 | S29: =R29-V29 -> 8.7311491e-09 | U29: =D29 -> MYR | V29: =T29 -> 0
A30: 7 | B30: Ann Joo Integrated Steel Sdn Bhd - TRi | C30: 501265 | D30: MYR | G30: 0 | R30: =G30+H30+J30+K30+I30-M30-O30-P30-Q30-N30 -> 0 | S30: =R30-V30 -> 0 | U30: =D30 -> MYR | V30: =T30 -> 0
A31: 8 | B31: Bahru Stainless Sdn Bhd 1 | C31: 501351 | D31: USD | H31: 30652750 | P31: 45250 | R31: =G31+H31+J31+K31+I31-M31-O31-P31-Q31-N31 -> 30607500 | S31: =R31-V31 -> 0 | T31: 7500000 | U31: =D31 -> USD | V31: =T31*$V$1 -> 30607500
A32: 9 | B32: Bahru Stainless Sdn Bhd 2 | C32: 501352 | D32: USD | H32: 71567250 | P32: 149750 | R32: =G32+H32+J32+K32+I32-M32-O32-P32-Q32-N32 -> 71417500 | S32: =R32-V32 -> 0 | T32: 17500000 | U32: =D32 -> USD | V32: =T32*$V$1 -> 71417500
A33: 10 | B33: Bateriku (M) Sdn Bhd | C33: 501306 | D33: MYR | G33: 4233375.2 | H33: 4278767.7 | R33: =G33+H33+J33+K33+I33-M33-O33-P33-Q33-N33 -> 8512143 | S33: =R33-V33 -> 0 | T33: 8512143 | U33: =D33 -> MYR | V33: =T33 -> 8512143
A34: 8 | B34: Bertambest Sdn Bhd | C34: 501137 | D34: MYR | G34: -4.6566129e-10 | R34: =G34+H34+J34+K34+I34-M34-O34-P34-Q34-N34 -> -4.6566129e-10 | S34: =R34-V34 -> -4.6566129e-10 | U34: =D34 -> MYR | V34: =T34 -> 0
A35: 11 | B35: Bhavani Foods (M) Sdn Bhd | C35: 501131 | D35: MYR | G35: 1887036.9 | H35: 473970.5 | M35: 519003.55 | R35: =G35+H35+J35+K35+I35-M35-O35-P35-Q35-N35 -> 1842003.8 | S35: =R35-V35 -> 0 | T35: 1842003.8 | U35: =D35 -> MYR | V35: =T35 -> 1842003.8
A36: 12 | B36: Bio Eneco Sdn Bhd | C36: 501035 | D36: MYR | G36: 2442000 | R36: =G36+H36+J36+K36+I36-M36-O36-P36-Q36-N36 -> 2442000 | S36: =R36-V36 -> 0 | T36: 2442000 | U36: =D36 -> MYR | V36: =T36 -> 2442000 | AB36: =H36+I36-M36-O36 -> 0 | AC36: =G36+H36+I36+J36-M36-O36-P36 -> 2442000
A37: 10 | B37: Bousted Petroleum Marketing | C37: 501086 | D37: USD | G37: 0 | R37: =G37+H37+J37+K37+I37-M37-O37-P37-Q37-N37 -> 0 | S37: =R37-V37 -> 0 | U37: =D37 -> USD | V37: =T37*$V$1 -> 0 | AB37: =H37+I37-M37-O37 -> 0 | AC37: =G37+H37+I37+J37-M37-O37-P37 -> 0
A38: 8 | B38: Bousted Petroleum Marketing | C38: 501156 | D38: USD | G38: 6.9849193e-10 | R38: =G38+H38+J38+K38+I38-M38-O38-P38-Q38-N38 -> 6.9849193e-10 | S38: =R38-V38 -> 6.9849193e-10 | U38: =D38 -> USD | V38: =T38*$V$1 -> 0
A39: 13 | B39: Choon Eng (Sarawak) Sdn Bhd | C39: 501142 | D39: MYR | G39: 6979414.4 | M39: 963000 | R39: =G39+H39+J39+K39+I39-M39-O39-P39-Q39-N39 -> 6016414.4 | S39: =R39-V39 -> 0 | T39: 6016414.4 | U39: =D39 -> MYR | V39: =T39 -> 6016414.4
A40: 14 | B40: Coco Oro Jewellery Sdn Bhd - SFi | C40: 501293 | D40: MYR | G40: 7987464 | H40: 1148016.8 | M40: 1138300 | R40: =G40+H40+J40+K40+I40-M40-O40-P40-Q40-N40 -> 7997180.8 | S40: =R40-V40 -> 0 | T40: 7997180.8 | U40: =D40 -> MYR | V40: =T40 -> 7997180.8
A41: 15 | B41: Coco Oro Jewellery Sdn Bhd - RCi | C41: 501318 | D41: MYR | G41: 1998000 | R41: =G41+H41+J41+K41+I41-M41-O41-P41-Q41-N41 -> 1998000 | S41: =R41-V41 -> 0 | T41: 1998000 | V41: =T41 -> 1998000
A42: 16 | B42: Enapak Packaging Sdn Bhd | C42: 501344 | D42: MYR | G42: 3001587.5 | H42: 2977456.5 | R42: =G42+H42+J42+K42+I42-M42-O42-P42-Q42-N42 -> 5979044 | S42: =R42-V42 -> 0 | T42: 5979044 | U42: MYR | V42: =T42 -> 5979044
A43: 17 | B43: Enviros Survey & Consultancy Sdn Bhd - RCi | C43: 501235 | D43: USD | G43: 4077500 | H43: 2467270.6 | J43: 2096.06 | M43: 2465761.6 | P43: 105.05 | R43: =G43+H43+J43+K43+I43-M43-O43-P43-Q43-N43 -> 4081000 | S43: =R43-V43 -> 0.010000001 | T43: 1000000 | U43: USD | V43: =T43*$V$1 -> 4081000
A44: 18 | B44: Enviros Survey & Consultancy Sdn Bhd - SFi | C44: 501323 | D44: USD | G44: 620207.81 | M44: 620207.81 | R44: =G44+H44+J44+K44+I44-M44-O44-P44-Q44-N44 -> 0 | S44: =R44-V44 -> 0 | T44: 0 | U44: MYR | V44: =T44 -> 0
...

Sheet Debtors Listing Islamic (Profit
A1: Profit Outstanding (MYR) for Islamic Financing as at 31st July 2026 | V1: USD | W1: ='Debtors Listing Islamic (Cost)'!V1 -> 4.081 | X1: EUR | Y1: ='Debtors Listing Islamic (Cost)'!X1 -> 4.7017 | Z1: SGD | AA1: ='Debtors Listing Islamic (Cost)'!Z1 -> 3.1854
V2: GBP | W2: ='Debtors Listing Islamic (Cost)'!V2 -> 5.4924 | X2: AUD | Y2: ='Debtors Listing Islamic (Cost)'!X2 -> 2.8734
A4: No. | B4: Company | C4: Customer Account | D4: Currency | E4: Remarks | F4: Audit Adjustment | G4: Opening | H4: Disbursement | I4: Adjustment/ Capitalisation | J4: Forex (+) | K4: Unearned Profit | L4: Rental (Ijarah) | M4: Cost Payment | N4: Profit Payment | O4: Adjustment/ Capitalisation | P4: Forex (-) | Q4: Unearned Profit | R4: Balance | U4: Base Currency COD & ARRD | W4: COD & ARRD in Local Currency
B6: Islamic Financing Facility
B8: Supplier Credit Islamic Financing Facility - Tawaruq
B9: Allied PT Resources Sdn Bhd | C9: 500685 | D9: MYR | G9: 0 | R9: =G9+H9+J9+K9+I9-M9-O9-P9-Q9-N9 -> 0
B10: Arab Malaysian Vegetable Oil Products Co Ltd | C10: 500548 | D10: USD | G10: 0 | R10: =G10+H10+J10+K10+I10-M10-O10-P10-Q10-N10 -> 0
B11: Arab Malaysian Vegetable Oil Products Co Ltd - Trade | C11: 500556 | D11: USD | G11: 0 | R11: =G11+H11+J11+K11+I11-M11-O11-P11-Q11-N11 -> 0
B12: Awin Resources (Malaysia) Ltd | C12: 500858 | D12: USD | G12: 0 | R12: =G12+H12+J12+K12+I12-M12-O12-P12-Q12-N12 -> 0
B13: Destini Prima Sdn Bhd | C13: 500731 | D13: USD | G13: 0 | R13: =G13+H13+J13+K13+I13-M13-O13-P13-Q13-N13 -> 0
B14: Central Sugar Refinery | C14: 500815 | D14: MYR | G14: 0 | R14: =G14+H14+J14+K14+I14-M14-O14-P14-Q14-N14 -> 0
B15: Continental Resources Sdn Bhd | C15: 500813 | D15: USD | G15: 0 | R15: =G15+H15+J15+K15+I15-M15-O15-P15-Q15-N15 -> 0
B16: EON Metal Technology Sdn Bhd | C16: 500830 | D16: USD | G16: 0 | R16: =G16+H16+J16+K16+I16-M16-O16-P16-Q16-N16 -> 0
B17: Destini Shipbuilding & Engineering | C17: 500908 | D17: EUR | G17: 0 | R17: =G17+H17+J17+K17+I17-M17-O17-P17-Q17-N17 -> 0
A18: 1 | B18: Aescomed Healthcare Sdn Bhd | C18: 501125 | D18: MYR | G18: 0 | R18: =G18+H18+J18+K18+I18-M18-O18-P18-Q18-N18 -> 0 | S18: =R18-W18 -> 0 | T18: =D18 -> MYR | W18: =U18 -> 0
A19: 1 | B19: ACE Champion Sdn Bhd | C19: 501285 | D19: MYR | G19: 53602.99 | K19: 28981.82 | N19: 21995.97 | R19: =G19+H19+J19+K19+I19-M19-O19-P19-Q19-N19 -> 60588.84 | S19: =R19-W19 -> -0.01051631 | T19: =D19 -> MYR | U19: 60588.851 | W19: =U19 -> 60588.851
A20: 2 | B20: Agro 19 Berhad | C20: 501111 | D20: MYR | G20: 80463.05 | K20: 52215.59 | N20: 83203.4 | R20: =G20+H20+J20+K20+I20-M20-O20-P20-Q20-N20 -> 49475.24 | S20: =R20-W20 -> -0.00033291231 | T20: =D20 -> MYR | U20: 49475.24 | W20: =U20 -> 49475.24
A21: 3 | B21: Agro 19 Berhad 2 | C21: 501172 | D21: MYR | G21: 519510.75 | K21: 185865.3 | N21: 583821.24 | R21: =G21+H21+J21+K21+I21-M21-O21-P21-Q21-N21 -> 121554.81 | S21: =R21-W21 -> 0.0060155752 | T21: =D21 -> MYR | U21: 121554.8 | W21: =U21 -> 121554.8
A22: 4 | B22: Agro 19 Berhad 3 | C22: 501291 | D22: MYR | G22: 726607.4 | K22: 264168.94 | N22: 26212.24 | R22: =G22+H22+J22+K22+I22-M22-O22-P22-Q22-N22 -> 964564.1 | S22: =R22-W22 -> -0.024193847 | T22: =D22 -> MYR | U22: 964564.12 | W22: =U22 -> 964564.12
A23: 5 | B23: Agro 19 Berhad 4 | C23: 501350 | D23: MYR | G23: 2161.65 | K23: 33505.48 | R23: =G23+H23+J23+K23+I23-M23-O23-P23-Q23-N23 -> 35667.13 | S23: =R23-W23 -> 0.0067123288 | T23: =D23 -> MYR | U23: 35667.123 | W23: =U23 -> 35667.123
A24: 6 | B24: Agro 19 Berhad - RCi | C24: 501356 | D24: MYR | G24: 0 | K24: 588.53 | R24: =G24+H24+J24+K24+I24-M24-O24-P24-Q24-N24 -> 588.53 | S24: =R24-W24 -> 0.0038736712 | T24: =D24 -> MYR | U24: 588.52613 | W24: =U24 -> 588.52613
A25: 7 | B25: AMC Cincaria Sdn Bhd | C25: 501129 | D25: MYR | G25: 16511.49 | K25: 14738.85 | N25: 13451.23 | R25: =G25+H25+J25+K25+I25-M25-O25-P25-Q25-N25 -> 17799.11 | S25: =R25-W25 -> 0.010273112 | T25: =D25 -> MYR | U25: 17799.1 | W25: =U25 -> 17799.1
A26: 6 | B26: Ann Joo Integrated Steel Sdn Bhd | C26: 501161 | D26: MYR | G26: -1.5734258e-10 | R26: =G26+H26+J26+K26+I26-M26-O26-P26-Q26-N26 -> -1.5734258e-10 | S26: =R26-W26 -> -1.5734258e-10 | T26: =D26 -> MYR | W26: =U26 -> 0
A27: 7 | B27: Ann Joo Integrated Steel Sdn Bhd - TRi | C27: 501265 | D27: MYR | G27: 0 | R27: =G27+H27+J27+K27+I27-M27-O27-P27-Q27-N27 -> 0 | S27: =R27-W27 -> 0 | T27: =D27 -> MYR | W27: =U27 -> 0
A28: 7 | B28: AT Precision Engineering Sdn Bhd | C28: 501231 | D28: MYR | G28: -7.2759576e-12 | R28: =G28+H28+J28+K28+I28-M28-O28-P28-Q28-N28 -> -7.2759576e-12 | S28: =R28-W28 -> -7.2759576e-12 | T28: =D28 -> MYR
A29: 8 | B29: Bahru Stainless Sdn Bhd 1 | C29: 501351 | D29: USD | G29: 0 | K29: 84700.01 | R29: =G29+H29+J29+K29+I29-M29-O29-P29-Q29-N29 -> 84700.01 | S29: =R29-W29 -> -0.011388889 | T29: =D29 -> USD | U29: 20754.722 | W29: =U29*$W$1 -> 84700.021
A30: 9 | B30: Bahru Stainless Sdn Bhd 2 | C30: 501352 | D30: USD | G30: 0 | K30: 176607.56 | R30: =G30+H30+J30+K30+I30-M30-O30-P30-Q30-N30 -> 176607.56 | S30: =R30-W30 -> 0.017777778 | T30: =D30 -> USD | U30: 43275.556 | W30: =U30*$W$1 -> 176607.54
A32: 10 | B32: Bateriku (M) Sdn Bhd | C32: 501306 | D32: MYR | G32: 57650.45 | K32: 39949.81 | R32: =G32+H32+J32+K32+I32-M32-O32-P32-Q32-N32 -> 97600.26 | S32: =R32-W32 -> 0.0012039973 | T32: =D32 -> MYR | U32: 97600.259 | W32: =U32 -> 97600.259
A33: 8 | B33: Bertambest Sdn Bhd | C33: 501137 | D33: MYR | G33: 0 | R33: =G33+H33+J33+K33+I33-M33-O33-P33-Q33-N33 -> 0 | S33: =R33-W33 -> 0 | T33: =D33 -> MYR | W33: =U33 -> 0
A34: 11 | B34: Bhavani Foods (M) Sdn Bhd | C34: 501131 | D34: MYR | G34: 19007.85 | K34: 10689.54 | N34: =9695.8+14.08 -> 9709.88 | R34: =G34+H34+J34+K34+I34-M34-O34-P34-Q34-N34 -> 19987.51 | S34: =R34-W34 -> -0.0041657315 | T34: =D34 -> MYR | U34: 19987.514 | W34: =U34 -> 19987.514
A35: 12 | B35: Bio Eneco Sdn Bhd | C35: 501035 | D35: MYR | G35: 10038.29 | K35: 14144.87 | R35: =G35+H35+J35+K35+I35-M35-O35-P35-Q35-N35 -> 24183.16 | S35: =R35-W35 -> 0.00054794521 | T35: =D35 -> MYR | U35: 24183.159 | W35: =U35 -> 24183.159 | AC35: =I35+J35+K35+L35-N35-O35-P35-Q35 -> 14144.87 | AD35: =G35+I35+J35+K35+L35-N35-O35-P35-Q35 -> 24183.16
A36: 10 | B36: Bousted Petroleum Marketing | C36: 501086 | D36: USD | G36: 0 | R36: =G36+H36+J36+K36+I36-M36-O36-P36-Q36-N36 -> 0 | S36: =R36-W36 -> 0 | T36: =D36 -> USD | W36: =U36*$W$1 -> 0
A37: 7 | B37: Bousted Petroleum Marketing | C37: 501156 | D37: USD | G37: 0 | R37: =G37+H37+J37+K37+I37-M37-O37-P37-Q37-N37 -> 0 | S37: =R37-W37 -> 0 | T37: =D37 -> USD | W37: =U37*$W$1 -> 0
A38: 13 | B38: Choon Eng (Sarawak) Sdn Bhd | C38: 501142 | D38: MYR | G38: 60030.59 | K38: 38987.58 | N38: 17633.72 | R38: =G38+H38+J38+K38+I38-M38-O38-P38-Q38-N38 -> 81384.45 | S38: =R38-W38 -> -0.012864142 | T38: =D38 -> MYR | U38: 81384.463 | W38: =U38 -> 81384.463
A39: 14 | B39: Coco Oro Jewellery Sdn Bhd - SFi | C39: 501293 | D39: MYR | G39: 70793.35 | K39: 54275.72 | N39: 28160.01 | R39: =G39+H39+J39+K39+I39-M39-O39-P39-Q39-N39 -> 96909.06 | S39: =R39-W39 -> -0.013535356 | T39: =D39 -> MYR | U39: 96909.074 | W39: =U39 -> 96909.074
A40: 15 | B40: Coco Oro Jewellery Sdn Bhd - RCi | C40: 501318 | D40: MYR | G40: 3525.24 | K40: 13660.3 | R40: =G40+H40+J40+K40+I40-M40-O40-P40-Q40-N40 -> 17185.54 | S40: =R40-W40 -> 0.0030136986 | T40: =D40 -> MYR | U40: 17185.537 | W40: =U40 -> 17185.537
A41: 16 | B41: Enapak Packaging Sdn Bhd | C41: 501344 | D41: MYR | G41: 5052.16 | K41: 29651.23 | R41: =G41+H41+J41+K41+I41-M41-O41-P41-Q41-N41 -> 34703.39 | S41: =R41-W41 -> 0.0011578082 | U41: 34703.389 | W41: =U41 -> 34703.389
A42: 17 | B42: Enviros Survey & Consultancy Sdn Bhd | C42: 501235 | D42: USD | G42: 65863.43 | I42: 19706.86 | J42: 105.05 | K42: =28101.48 -> 28101.48 | N42: 49623.43 | R42: =G42+H42+J42+K42+I42-M42-O42-P42-Q42-N42 -> 64153.39 | S42: =R42-W42 -> -0.0032971179 | T42: =D42 -> USD | U42: 15720.018 | W42: =U42*$W$1 -> 64153.393
A43: 18 | B43: Enviros Survey & Consultancy Sdn Bhd - SFi | C43: 501323 | D43: MYR | G43: 9145.02 | K43: 416.44 | N43: 9561.45 | O43: 0.01 | R43: =G43+H43+J43+K43+I43-M43-O43-P43-Q43-N43 -> 0 | S43: =R43-W43 -> 0 | T43: MYR | U43: 0 | W43: =U43 -> 0
A44: 19 | B44: Evergreen Fibreboard Berhad | C44: 501290 | D44: MYR | G44: 73546.84 | K44: 57276.16 | N44: 34027.4 | R44: =G44+H44+J44+K44+I44-M44-O44-P44-Q44-N44 -> 96795.6 | S44: =R44-W44 -> -0.01369863 | T44: =D44 -> MYR | U44: 96795.614 | W44: =U44 -> 96795.614
...

Sheet Modification MORA & R&R
E1: 46204 | F1: 46174
D2: USD | E2: 4.0775 | F2: 4.0775 | I2: Impaired
D3: EUR | E3: 4.6457 | F3: 4.6457
D4: RM | E4: 1 | F4: 1
B5: 2022
B6: No. | C6: Borrower code | D6: GL Code | E6: Borrower | F6: Trade/ Non trade | G6: Currency | H6: SME/NON SME | J6: Islamic/ conventional | K6: SLO acceptance date | L6: Auto Mora/Mora/Non-auto mora (R&R) | M6: Modification impact (Original Currency) | N6: Amortisation in July 2026 | O6: Revised Modification impact (Original Currency) | P6: Fx | Q6: Modification impact (RM)
B7: 1 | C7: 501010 | D7: 2230005 | E7: Malaysian Phosphate Additives (Sarawak) Sdn Bhd | F7: Non trade | G7: USD | H7: Non SME | J7: Islamic | K7: 44831 | L7: R&R | M7: 2604.1799 | N7: =13.93-[3]JV!F47 -> -2604.18 | O7: =SUM(M7:N7) -> -0.00012010165 | P7: =SUMIF($D$2:$D$4,G7,$E$2:$E$4) -> 4.0775 | Q7: =O7*P7 -> -0.00048971447 | U7: 4.728
Q8: =SUBTOTAL(9,Q7:Q7) -> -0.00048971447
G9: RM | M9: =SUMIF($G$7:$G$7,G9,$M$7:$M$7) -> 0 | N9: =SUMIF($G$7:$G$7,G9,$N$7:$N$7) -> 0 | O9: =SUMIF($G$7:$G$7,G9,$O$7:$O$7) -> 0
G10: USD | M10: =SUMIF($G$7:$G$7,G10,$M$7:$M$7) -> 2604.1799 | N10: =SUMIF($G$7:$G$7,G10,$N$7:$N$7) -> -2604.18 | O10: =SUMIF($G$7:$G$7,G10,$O$7:$O$7) -> -0.00012010165
B13: 2023
B14: No. | C14: Borrower code | D14: GL Code | E14: Borrower | F14: Trade/ Non trade | G14: Currency | H14: SME/NON SME | J14: Islamic/ conventional | K14: SLO acceptance date | L14: Auto Mora/Mora/Non-auto mora (R&R) | M14: Modification impact (Original Currency) | N14: =N6 -> Amortisation in July 2026 | O14: Revised Modification impact (Original Currency) | P14: Fx | Q14: Modification impact (RM)
B15: 1 | C15: 500943 | D15: 2230005 | E15: PWN Excellence Sdn Bhd 3 | F15: Non trade | G15: RM | H15: SME | J15: Islamic | K15: 45149 | L15: R&R | M15: 47984.742 | N15: -293.3 | O15: =SUM(M15:N15) -> 47691.442 | P15: =SUMIF($D$2:$D$4,G15,$E$2:$E$4) -> 1 | Q15: =O15*P15 -> 47691.442 | U15: 1
Q16: =SUBTOTAL(9,Q15:Q15) -> 47691.442
G17: RM | M17: =SUMIF($G$15:$G$15,G17,$M$15:$M$15) -> 47984.742 | N17: =SUMIF($G$15:$G$15,G17,$N$15:$N$15) -> -293.3 | O17: =SUMIF($G$15:$G$15,G17,$O$15:$O$15) -> 47691.442
G18: USD | M18: =SUMIF($G$15:$G$15,G18,$M$15:$M$15) -> 0 | N18: =SUMIF($G$15:$G$15,G18,$N$15:$N$15) -> 0 | O18: =SUMIF($G$15:$G$15,G18,$O$15:$O$15) -> 0
B20: 2024
B21: No. | C21: Borrower code | D21: GL Code | E21: Borrower | F21: Trade/ Non trade | G21: Currency | H21: SME/NON SME | J21: Islamic/ conventional | K21: SLO acceptance date | L21: Auto Mora/Mora/Non-auto mora (R&R) | M21: Modification impact (Original Currency) | N21: =N6 -> Amortisation in July 2026 | O21: Revised Modification impact (Original Currency) | P21: Fx | Q21: Modification impact (RM)
B22: 1 | C22: 501050 | D22: 2230005 | E22: Ingress Industrial (Thailand) Co Ltd | F22: Non trade | G22: RM | H22: Non SME | J22: Islamic | K22: 45625 | L22: R&R | M22: -1155735 | N22: 31875.41 | O22: =SUM(M22:N22) -> -1123859.5 | P22: =SUMIF($D$2:$D$4,G22,$E$2:$E$4) -> 1 | Q22: =O22*P22 -> -1123859.5
Q23: =SUBTOTAL(9,Q22:Q22) -> -1123859.5
G24: RM | M24: =SUMIF($G$22,G24,$M$22) -> -1155735 | N24: =SUMIF($G$22,G24,$N$22) -> 31875.41 | O24: =SUMIF($G$22,G24,$O$22) -> -1123859.5
G25: USD | M25: =SUMIF($G$22,G25,$M$22) -> 0 | N25: =SUMIF($G$22,G25,$N$22) -> 0 | O25: =SUMIF($G$22,G25,$O$22) -> 0
B28: 2025
B29: No. | C29: Borrower code | D29: GL Code | E29: Borrower | F29: Trade/ Non trade | G29: Currency | H29: SME/NON SME | J29: Islamic/ conventional | K29: SLO acceptance date | L29: Auto Mora/Mora/Non-auto mora (R&R) | M29: Modification impact (Original Currency) | N29: =N6 -> Amortisation in July 2026 | O29: Revised Modification impact (Original Currency) | P29: Fx | Q29: Modification impact (RM)
B30: 1 | C30: 501215 | D30: 2230005 | E30: JFC Food Industries Sdn Bhd | F30: Non trade | G30: RM | H30: SME | J30: Islamic | K30: 45896 | L30: R&R | M30: 162.39322 | N30: 142.9 | O30: =SUM(M30:N30) -> 305.29322 | P30: =SUMIF($D$2:$D$4,G30,$E$2:$E$4) -> 1 | Q30: =O30*P30 -> 305.29322
B31: 2 | C31: 501307 | D31: 2230005 | E31: YH Polymer Sdn Bhd | F31: Non trade | G31: RM | H31: SME | J31: Islamic | K31: 45971 | L31: R&R | M31: 463.0602 | N31: 340.58 | O31: =SUM(M31:N31) -> 803.6402 | P31: =SUMIF($D$2:$D$4,G31,$E$2:$E$4) -> 1 | Q31: =O31*P31 -> 803.6402
Q32: =SUBTOTAL(9,Q30:Q31) -> 1108.9334
G33: RM | M33: =SUMIF($G$30:$G$31,G33,$M$30:$M$31) -> 625.45342 | N33: =SUMIF($G$30:$G$31,G33,$N$30:$N$31) -> 483.48 | O33: =SUMIF($G$30:$G$31,G33,$O$30:$O$31) -> 1108.9334
G34: USD | M34: =SUMIF($G$30:$G$31,G34,$M$30:$M$31) -> 0 | N34: =SUMIF($G$30:$G$31,G34,$N$30:$N$31) -> 0 | O34: =SUMIF($G$30:$G$31,G34,$O$30:$O$31) -> 0
B36: 2026
B37: No. | C37: Borrower code | D37: GL Code | E37: Borrower | F37: Trade/ Non trade | G37: Currency | H37: SME/NON SME | J37: Islamic/ conventional | K37: SLO acceptance date | L37: Auto Mora/Mora/Non-auto mora (R&R) | M37: Modification impact (Original Currency) | N37: =N14 -> Amortisation in July 2026 | O37: Revised Modification impact (Original Currency) | P37: Fx | Q37: Modification impact (RM)
B38: 1 | C38: 501336 | D38: 2230005 | E38: KENNWU MANUFACTURING (M) SDN. BHD. | F38: Non trade | G38: RM | H38: SME | J38: Islamic | K38: 46129 | L38: R&R | M38: 419.84274 | N38: 206.72 | O38: =SUM(M38:N38) -> 626.56274 | P38: =SUMIF($D$2:$D$4,G38,$E$2:$E$4) -> 1 | Q38: =O38*P38 -> 626.56274
B39: 2 | M39: 0 | O39: =SUM(M39:N39) -> 0 | P39: =SUMIF($D$2:$D$4,G39,$E$2:$E$4) -> 0 | Q39: =O39*P39 -> 0
Q40: =SUBTOTAL(9,Q38:Q39) -> 626.56274
G41: RM | M41: =SUMIF($G$30:$G$31,G41,$M$30:$M$31) -> 625.45342 | N41: =SUMIF($G$30:$G$31,G41,$N$30:$N$31) -> 483.48 | O41: =SUMIF($G$30:$G$31,G41,$O$30:$O$31) -> 1108.9334
G42: USD | M42: =SUMIF($G$30:$G$31,G42,$M$30:$M$31) -> 0 | N42: =SUMIF($G$30:$G$31,G42,$N$30:$N$31) -> 0 | O42: =SUMIF($G$30:$G$31,G42,$O$30:$O$31) -> 0
G44: TOTAL | Q44: =Q8+Q16+Q23+Q32+Q40 -> -1074432.6
Q46: As per listing | R46: SAP | S46: Variance
O47: 134003 | P47: Conventional | Q47: =SUMIF($J$5:$J$39,P47,$Q$5:$Q$39) -> 0 | R47: 0 | S47: =Q47-R47 -> 0
O48: 2230005 | P48: Islamic | Q48: =SUMIF($J$5:$J$39,P48,$Q$5:$Q$39) -> -1074432.6 | S48: =Q48-R48 -> -1074432.6
...

Sheet Debtors Listing Conv Jan 2024
A1: Customer Balances as at January 2024
A3: Customer Account Number | B3: Customer Class & Industry | C3: Customer Name | D3: Loan Currency | E3: Opening Principal | F3: Disbursement | G3: Adjustment Capitalization | H3: Forex ( + ) | I3: Repayment | J3: Adjustment Capitalization | K3: Forex ( - ) | L3: Closing Principal
A5: 500937 | C5: THE MINISTRY OF FINANCE LAOS 2 | D5: USD | E5: 2.2491e+08 | F5: 0 | G5: 0 | H5: 6835500 | I5: 0 | J5: 0 | K5: 0 | L5: 2.317455e+08
B6: Active (Cross Border Credit) (Buyer Credit) | E6: 2.2491e+08 | F6: 0 | G6: 0 | H6: 6835500 | I6: 0 | J6: 0 | K6: 0 | L6: 2.317455e+08
A8: 500749 | C8: ISTANBUL SABIHA GOKCEN ULUSLARARASI | D8: EUR | E8: 142150400 | F8: 0 | G8: 0 | H8: 1134000 | I8: 0 | J8: 0 | K8: 0 | L8: 143284400
B9: Active (Overseas Investment) | E9: 142150400 | F9: 0 | G9: 0 | H9: 1134000 | I9: 0 | J9: 0 | K9: 0 | L9: 143284400
A11: 500640 | C11: OM MATERIAL (SARAWAK) SDN BHD | D11: USD | E11: 88355287 | F11: 0 | G11: 0 | H11: 2685307.7 | I11: 0 | J11: 0 | K11: 0 | L11: 91040594
A12: 500642 | C12: OM MATERIAL (SARAWAK) 2 | D12: USD | E12: 1.2136781e+08 | F12: 0 | G12: 0 | H12: 3688629.4 | I12: 0 | J12: 0 | K12: 0 | L12: 1.2505644e+08
A13: 501051 | C13: YINSON BORONIA PRODUCTION B.V (2) | D13: USD | E13: 5.3559792e+08 | F13: 0 | G13: 0 | H13: 16277976 | I13: -8342838 | J13: 0 | K13: 0 | L13: 5.4353306e+08
A14: 501072 | C14: SERI ERLANG (SINGAPORE) PTE LTD | D14: USD | E14: 29462572 | F14: 0 | G14: 0 | H14: 895431.12 | I14: 0 | J14: 0 | K14: 0 | L14: 30358004
A15: 501073 | C15: SERI EVEREST (SINGAPORE) PTE LTD | D15: USD | E15: 29465011 | F15: 0 | G15: 0 | H15: 895505.24 | I15: 0 | J15: 0 | K15: 0 | L15: 30360516
A16: 501075 | C16: SERI ELBERT (SINGAPORE) PTE LTD | D16: USD | E16: 29129172 | F16: 0 | G16: 0 | H16: 884302.85 | I16: -391364.55 | J16: 0 | K16: 0 | L16: 29622110
A17: 501076 | C17: SERI EMORY (SINGAPORE) PTE LTD | D17: USD | E17: 29266433 | F17: 0 | G17: 0 | H17: 887990.85 | I17: -581496.79 | J17: 0 | K17: 0 | L17: 29572927
A18: 501077 | C18: SERI EMEI (SINGAPORE) PTE LTD | D18: USD | E18: 30027308 | F18: 0 | G18: 0 | H18: 911068.12 | I18: -600116.1 | J18: 0 | K18: 0 | L18: 30338260
A19: 501078 | C19: SERI EMPEROR (SINGAPORE) PTE LTD | D19: USD | E19: 29266433 | F19: 0 | G19: 0 | H19: 887990.85 | I19: -581496.79 | J19: 0 | K19: 0 | L19: 29572927
B20: Active (Overseas Projec Fin) | E20: 9.2193794e+08 | F20: 0 | G20: 0 | H20: 28014202 | I20: -10497312 | J20: 0 | K20: 0 | L20: 9.3945483e+08
A22: 500693 | C22: PERUSAHAAN OTOMOBIL NASIONAL (VF) | D22: MYR | E22: 884238.97 | F22: 373789.52 | G22: 0 | H22: 0 | I22: -448532.63 | J22: 0 | K22: 0 | L22: =SUM(E22:K22) -> 809495.86
A23: 500724 | C23: OM MATERIALS (SARAWAK) SDN BHD | D23: USD | E23: 91064746 | F23: 19369912 | G23: 0 | H23: 2370770.8 | I23: -32968618 | J23: 0 | K23: 0 | L23: =SUM(E23:K23) -> 79836811
A24: 500840 | C24: PERTAMA FERROALLOYS SDN BHD | D24: USD | E24: 44918873 | F24: 0 | G24: 0 | H24: 1354613.1 | I24: -24980946 | J24: 0 | K24: 0 | L24: =SUM(E24:K24) -> 21292540
B25: Active (Supplier Credit) (Trade Finance) | E25: =SUM(E22:E24) -> 1.3686786e+08 | F25: =SUM(F22:F24) -> 19743701 | G25: 0 | H25: =SUM(H22:H24) -> 3725383.9 | I25: =SUM(I22:I24) -> -58398097 | J25: 0 | K25: 0 | L25: =SUM(L22:L24) -> 1.0193885e+08
A27: 500400 | C27: THE REPUBLIC OF IRAQ | D27: USD | E27: 1582620.2 | F27: 0 | G27: 0 | H27: 48099.19 | I27: 0 | J27: 0 | K27: 0 | L27: 1630719.4
A28: 500401 | C28: THE REPUBLIC OF SEYCHELLES | D28: USD | E28: 15241920 | F28: 0 | G28: 0 | H28: 459248.4 | I28: -1567158.8 | J28: 0 | K28: 0 | L28: 14134010
A29: 501098 | C29: Sarawak Petchem Sdn Bhd (TL) | D29: USD | E29: 44884213 | F29: 12470012 | G29: 0 | H29: 1366765.3 | I29: 0 | J29: 0 | K29: 0 | L29: 58720990
A30: 501100 | C30: BUMI ARMADA LABUAN LIMITED | D30: USD | E30: 91800000 | F30: 0 | G30: 0 | H30: 2790000 | I30: 0 | J30: 0 | K30: 0 | L30: 94590000
B31: Active (Term Loan) | E31: 1.5350875e+08 | F31: 12470012 | G31: 0 | H31: 4664112.8 | I31: -1567158.8 | J31: 0 | K31: 0 | L31: 1.6907572e+08
A33: 500010 | C33: PT BUMI INTERNATIONAL TANKERS | D33: USD | E33: 12893037 | F33: 0 | G33: 0 | H33: 391847.2 | I33: 0 | J33: 0 | K33: 0 | L33: 13284884
A34: 500011 | C34: PT LAYAR SENTOSA | D34: USD | E34: 13089115 | F34: 0 | G34: 0 | H34: 397806.41 | I34: 0 | J34: 0 | K34: 0 | L34: 13486921
A35: 500039 | C35: PT MAHAKARYA INTI BUANA | D35: USD | E35: 11947770 | F35: 0 | G35: 0 | H35: 363118.49 | I35: 0 | J35: 0 | K35: 0 | L35: 12310888
A36: 500913 | C36: PT SRIWIJAYA AIR | D36: USD | E36: 3.7133704e+08 | F36: 0 | G36: 0 | H36: 11285734 | I36: 0 | J36: 0 | K36: 0 | L36: 3.8262278e+08
B37: Impaired Loan (Buyer Credit) | E37: 4.0926696e+08 | F37: 0 | G37: 0 | H37: 12438506 | I37: 0 | J37: 0 | K37: 0 | L37: 4.2170547e+08
A39: 500577 | C39: NIRMALA VILAS RESTAURANT SDN BHD | D39: MYR | E39: 747562.14 | F39: 0 | G39: 0 | H39: 0 | I39: 0 | J39: 0 | K39: 0 | L39: 747562.14
A40: 500758 | C40: 3 PLUS1 STUDIO SDN BHD 2 | D40: MYR | E40: 975206.98 | F40: 0 | G40: 0 | H40: 0 | I40: 0 | J40: 0 | K40: 0 | L40: 975206.98
A41: 500852 | C41: NEE ASSETS SDN BHD | D41: MYR | E41: 539751.12 | F41: 0 | G41: 0 | H41: 0 | I41: 0 | J41: 0 | K41: 0 | L41: 539751.12
A42: 500866 | C42: NEE ASSETS SDN BHD 1 | D42: MYR | E42: 116666.69 | F42: 0 | G42: 0 | H42: 0 | I42: 0 | J42: 0 | K42: 0 | L42: 116666.69
B43: Impaired Loan (Malaysia Kitchen Fin) | E43: 2379186.9 | F43: 0 | G43: 0 | H43: 0 | I43: 0 | J43: 0 | K43: 0 | L43: 2379186.9
A45: 501045 | C45: SAPURA TMC SDN BHD | D45: USD | E45: 84867032 | F45: 0 | G45: 0 | H45: 2579292.1 | I45: 0 | J45: 0 | K45: 0 | L45: 87446324
B46: Impaired Loan (Overseas Investment) | E46: 84867032 | F46: 0 | G46: 0 | H46: 2579292.1 | I46: 0 | J46: 0 | K46: 0 | L46: 87446324
A48: 500042 | C48: PT EDEN CAPITAL INDONESIA | D48: USD | E48: 13943180 | F48: 0 | G48: 0 | H48: 423763.31 | I48: 0 | J48: 0 | K48: 0 | L48: 14366943
A49: 500522 | C49: VIRTUAL PEAKS GROUP SDN BHD | D49: USD | E49: 7475829.4 | F49: 0 | G49: 0 | H49: 227206.58 | I49: 0 | J49: 0 | K49: 0 | L49: 7703036
A50: 500557 | C50: MARKMORE ENERGY 1 | D50: USD | E50: 1.6073475e+08 | F50: 0 | G50: 0 | H50: 4885075.8 | I50: 0 | J50: 0 | K50: 0 | L50: 1.6561983e+08
...

Sheet FS Feb 2022

Sheet Debtors Listing (C) Nov2020
A1: Customer Balances as at November 2020
A3: Customer Account Number | B3: Customer Class & Industry | C3: Customer Name | D3: Loan Currency | E3: Opening Principal | F3: Disbursement | G3: Adjustment Capitalization | H3: Forex ( + ) | I3: Repayment | J3: Adjustment Capitalization | K3: Forex ( - ) | L3: Closing Principal
A5: 500470 | C5: MINISTRY OF FINANCE - LAO PDR | D5: USD | E5: 87763812 | F5: 0 | G5: 0 | H5: 0 | I5: 0 | J5: 0 | K5: -1679437.5 | L5: 86084375
A6: 500937 | C6: MINISTRY OF FINANCE LAOS 2 | D6: USD | E6: 2.4977166e+08 | F6: 18880062 | G6: 0 | H6: 0 | I6: 0 | J6: 0 | K6: -5042298.8 | L6: 2.6360943e+08
B7: Active (Cross Border Credit) (Buyer Credit) | E7: 3.3753547e+08 | F7: 18880062 | G7: 0 | H7: 0 | I7: 0 | J7: 0 | K7: -6721736.3 | L7: 3.496938e+08
A9: 500878 | C9: WOK DELIGHTS SDN BHD | D9: MYR | E9: 1195048.9 | F9: 0 | G9: 0 | H9: 0 | I9: -66391.6 | J9: 0 | K9: 0 | L9: 1128657.3
B10: Active (Malaysia Kitchen Fin) | E10: 1195048.9 | F10: 0 | G10: 0 | H10: 0 | I10: -66391.6 | J10: 0 | K10: 0 | L10: 1128657.3
A12: 500629 | C12: FACADE TREATMENT (Term Loan)CBC | D12: MYR | E12: 1118253.9 | F12: 0 | G12: 0 | H12: 0 | I12: -95556.64 | J12: 0 | K12: 0 | L12: 1022697.2
B13: Active (Overseas Contract Fi) (Term Loan) | E13: 1118253.9 | F13: 0 | G13: 0 | H13: 0 | I13: -95556.64 | J13: 0 | K13: 0 | L13: 1022697.2
A15: 500679 | C15: BUMI ARMADA CAPITAL OFFSHORE LTD | D15: USD | E15: 2.0265414e+08 | F15: 0 | G15: 0 | H15: 0 | I15: -290212.79 | J15: 0 | K15: -3876864.9 | L15: 1.9848706e+08
A16: 500708 | C16: SAPURAKENCANA TMC SDN BHD (1) | D16: USD | E16: 15244632 | F16: 0 | G16: 0 | H16: 0 | I16: 0 | J16: 0 | K16: -291719.43 | L16: 14952913
A17: 500709 | C17: SAPURAKENCANA TMC SDN BHD (2) | D17: USD | E17: 61682670 | F17: 0 | G17: 0 | H17: 0 | I17: 0 | J17: 0 | K17: -1180352 | L17: 60502318
A18: 500749 | C18: ISTANBUL SABIHA GOKCEN ULUSLARARASI | D18: EUR | E18: 186644150 | F18: 0 | G18: 0 | H18: 1282050 | I18: 0 | J18: 0 | K18: 0 | L18: 187926200
B19: Active (Overseas Investment) | E19: 4.6622559e+08 | F19: 0 | G19: 0 | H19: 1282050 | I19: -290212.79 | J19: 0 | K19: -5348936.3 | L19: 4.6186849e+08
A21: 500271 | C21: MBI Development D.O.O, Bosnia&Herze | D21: EUR | E21: 4906248.4 | F21: 0 | G21: 0 | H21: 33700.84 | I21: 0 | J21: 0 | K21: 0 | L21: 4939949.2
A22: 500590 | C22: MBI Development 2 | D22: EUR | E22: 5812039.9 | F22: 0 | G22: 0 | H22: 39922.65 | I22: 0 | J22: 0 | K22: 0 | L22: 5851962.6
A23: 500640 | C23: OM MATERIAL (SARAWAK) SDN BHD | D23: USD | E23: 1.2011245e+08 | F23: 0 | G23: 0 | H23: 0 | I23: 0 | J23: 0 | K23: -2298457.1 | L23: 1.17814e+08
A24: 500642 | C24: OM MATERIAL (SARAWAK) 2 | D24: USD | E24: 1.6285676e+08 | F24: 0 | G24: 0 | H24: 0 | I24: 0 | J24: 0 | K24: -3116406.8 | L24: 1.5974035e+08
A25: 500805 | C25: Armada Kraken Pte Ltd (OPF) | D25: USD | E25: 1.3147652e+08 | F25: 0 | G25: 0 | H25: 0 | I25: 0 | J25: 0 | K25: -2515918.5 | L25: 1.289606e+08
A26: 500807 | C26: Pertama Ferroalloys Sdn Bhd (2) | D26: USD | E26: 74609543 | F26: 0 | G26: 0 | H26: 0 | I26: 0 | J26: 0 | K26: -1427719 | L26: 73181824
A27: 500808 | C27: Pertama Ferroalloys Sdn Bhd (1) | D27: USD | E27: 46006709 | F27: 0 | G27: 0 | H27: 0 | I27: 0 | J27: 0 | K27: -880378.72 | L27: 45126331
A28: 500827 | C28: Pertama Ferroalloys Sdn Bhd (3) | D28: USD | E28: 1.0100638e+08 | F28: 0 | G28: 0 | H28: 0 | I28: 0 | J28: 0 | K28: -1932845.6 | L28: 99073530
A29: 500885 | C29: SUPERBOOM PROJECTS SDN BHD | D29: USD | E29: 82823896 | F29: 0 | G29: 0 | H29: 0 | I29: 0 | J29: 0 | K29: -1584907.9 | L29: 81238988
A30: 500905 | C30: ZICO HOLDINGS INC (OPF) | D30: SGD | E30: 2468116.2 | F30: 0 | G30: 0 | H30: 3787.29 | I30: -124111.39 | J30: 0 | K30: 0 | L30: 2347792.1
A31: 500914 | C31: IMPIANA UBUD (LABUAN) CO. LTD. | D31: USD | E31: 90775825 | F31: 0 | G31: 0 | H31: 0 | I31: 0 | J31: 0 | K31: -1737075 | L31: 89038750
A32: 500927 | C32: BRITISH UNIVERSITY VIETNAM | D32: USD | E32: 78180915 | F32: 0 | G32: 0 | H32: 0 | I32: 0 | J32: 0 | K32: -1496060.3 | L32: 76684854
A33: 501031 | C33: YINSON BORONIA PRODUCTION BV | D33: USD | E33: 0 | F33: 19890123 | G33: 0 | H33: 24435.04 | I33: 0 | J33: 0 | K33: 0 | L33: 19914558
B34: Active (Overseas Projec Fin) | E34: 9.010354e+08 | F34: 19890123 | G34: 0 | H34: 101845.82 | I34: -124111.39 | J34: 0 | K34: -16989769 | L34: 9.0391349e+08
A36: 500538 | C36: MIR VALVE SDN BHD | D36: USD | E36: 11491657 | F36: 1925466.8 | G36: 2.91 | H36: 0 | I36: -261316.26 | J36: 0 | K36: -235354.63 | L36: 12920455
A37: 500693 | C37: PERUSAHAAN OTOMOBIL NASIONAL (VF) | D37: MYR | E37: 10699919 | F37: 4406387.5 | G37: 0 | H37: 0 | I37: -5425782.7 | J37: 0 | K37: 0 | L37: 9680523.9
A38: 500724 | C38: OM Material (Sarawak) Sdn Bhd | D38: USD | E38: 66417050 | F38: 26089648 | G38: 0 | H38: 0 | I38: -16624375 | J38: 0 | K38: -1475148.2 | L38: 74407175
A39: 500840 | C39: Pertama Ferroalloys (Trade) | D39: USD | E39: 26587288 | F39: 0 | G39: 0 | H39: 0 | I39: -9177981.3 | J39: 0 | K39: -374502.45 | L39: 17034805
B40: Active (Supplier Credit) (Trade Finance) | E40: =SUM(E36:E39) -> 1.1519591e+08 | F40: 32421503 | G40: 2.91 | H40: 0 | I40: -31489455 | J40: 0 | K40: -2085005.2 | L40: =SUM(L36:L39) -> 1.1404296e+08
A42: 501000 | C42: Brahim's Overseas Venture Sdn Bhd | D42: MYR | E42: 15467576 | F42: 0 | G42: 0 | H42: 0 | I42: 0 | J42: 0 | K42: 0 | L42: 15467576
B43: Active (Term Loan) | E43: 15467576 | F43: 0 | G43: 0 | H43: 0 | I43: 0 | J43: 0 | K43: 0 | L43: 15467576
A45: 500010 | C45: PT BUMI INTERNATIONAL TANKERS | D45: USD | E45: 11669743 | F45: 0 | G45: 0 | H45: 0 | I45: 0 | J45: 0 | K45: -223310.75 | L45: 11446432
A46: 500011 | C46: PT LAYAR SENTOSA | D46: USD | E46: 11847217 | F46: 0 | G46: 0 | H46: 0 | I46: 0 | J46: 0 | K46: -226706.87 | L46: 11620510
A47: 500042 | C47: PT EDEN CAPITAL INDONESIA | D47: USD | E47: 12629069 | F47: 0 | G47: 0 | H47: 0 | I47: 0 | J47: -8820 | K47: -241499.52 | L47: 12378749
A48: 500265 | C48: PT SARI INDAH LESTARI | D48: USD | E48: 74284996 | F48: 0 | G48: 0 | H48: 0 | I48: 0 | J48: 0 | K48: -1421508.6 | L48: 72863488
A49: 500274 | C49: HONDAAFUSHI INVESTMENT PVT LTD | D49: USD | E49: 36950043 | F49: 0 | G49: 0 | H49: 0 | I49: 0 | J49: 0 | K49: -707071.48 | L49: 36242972
...

Sheet Principal Nov2020
A1: EXIM Bank of Malaysia Customer Balances in Local Currency Time 17:47:12 Date 02.12.2020
A2: Kuala Lumpur RFDSLD00/EIDIL Page 1
A3: Carryforwd Perio 01 - 10 2020 Reporting Period 11 - 11 2020
D5: CoCd | F5: Reconciliation acct | I5: Customer | J5: SearchTerm | K5: SGL Ind. | L5: Crcy | N5: Balance Carryforward | P5: Debit rept.period | Q5: Credit report per. | R5: Accumulated balance
D7: EXIM | F7: 138901 | I7: 500010 | J7: PT BUMI | L7: MYR | N7: 9502406.7 | P7: 0 | Q7: 0 | R7: 9502406.7
D8: EXIM | F8: 138901 | I8: 500010 | J8: PT BUMI | K8: N | L8: MYR | N8: 2167336.4 | P8: 10774270 | Q8: 10997580 | R8: 1944025.6
D9: EXIM | F9: 138901 | I9: 500011 | J9: PTLAYAR | L9: MYR | N9: 9722052.6 | P9: 0 | Q9: 0 | R9: 9722052.6
D10: EXIM | F10: 138901 | I10: 500011 | J10: PTLAYAR | K10: N | L10: MYR | N10: 2125164.5 | P10: 10867255 | Q10: 11093962 | R10: 1898457.6
D11: EXIM | F11: 138901 | I11: 500039 | J11: PTMAHAKARY | L11: MYR | N11: -11346186 | P11: 0 | Q11: 0 | R11: -11346186
D12: EXIM | F12: 138901 | I12: 500039 | J12: PTMAHAKARY | K12: N | L12: MYR | N12: 23135838 | P12: 32217914 | Q12: 32443519 | R12: 22910233
D13: EXIM | F13: 138901 | I13: 500042 | J13: PTEDEN | L13: MYR | N13: 10149768 | P13: 0 | Q13: 8820 | R13: 10140948
D14: EXIM | F14: 138901 | I14: 500042 | J14: PTEDEN | K14: N | L14: MYR | N14: 2479301 | P14: 2279912.8 | Q14: 2521412.3 | R14: 2237801.5
D15: EXIM | F15: 138901 | I15: 500187 | J15: JEWEL | L15: MYR | N15: 26832.06 | P15: 0 | Q15: 0 | R15: 26832.06
D16: EXIM | F16: 138901 | I16: 500197 | J16: VEHENG | L16: MYR | N16: 8200000 | P16: 0 | Q16: 0 | R16: 8200000
D17: EXIM | F17: 138901 | I17: 500206 | J17: BESTEEL | L17: MYR | N17: -2887257 | P17: 0 | Q17: 0 | R17: -2887257
D18: EXIM | F18: 138901 | I18: 500206 | J18: BESTEEL | K18: N | L18: MYR | N18: 8738355.6 | P18: 12226888 | Q18: 12338854 | R18: 8626389.7
D19: EXIM | F19: 138901 | I19: 500265 | J19: PTSARI | L19: MYR | N19: 61312933 | P19: 0 | Q19: 0 | R19: 61312933
D20: EXIM | F20: 138901 | I20: 500265 | J20: PTSARI | K20: N | L20: MYR | N20: 12972063 | P20: 22200738 | Q20: 23622246 | R20: 11550555
D21: EXIM | F21: 138901 | I21: 500271 | J21: MBI | L21: MYR | N21: 4970461.6 | P21: 0 | Q21: 0 | R21: 4970461.6
D22: EXIM | F22: 138901 | I22: 500271 | J22: MBI | K22: N | L22: MYR | N22: -64213.2 | P22: 4979599.2 | Q22: 4945898.4 | R22: -30512.36
D23: EXIM | F23: 138901 | I23: 500274 | J23: HONDAAFUSH | L23: MYR | N23: 27577487 | P23: 0 | Q23: 0 | R23: 27577487
D24: EXIM | F24: 138901 | I24: 500274 | J24: HONDAAFUSH | K24: N | L24: MYR | N24: 9372556.8 | P24: 8847570.3 | Q24: 9554641.8 | R24: 8665485.3
D25: EXIM | F25: 138901 | I25: 500297 | J25: PHOENIX111 | L25: MYR | N25: 3069452.3 | P25: 0 | Q25: 0 | R25: 3069452.3
D26: EXIM | F26: 138901 | I26: 500297 | J26: PHOENIX111 | K26: N | L26: MYR | N26: 851383.63 | P26: 8320657.9 | Q26: 8395702.8 | R26: 776338.71
D27: EXIM | F27: 138901 | I27: 500400 | J27: IRAQ | L27: MYR | N27: 1690251.4 | P27: 0 | Q27: 0 | R27: 1690251.4
D28: EXIM | F28: 138901 | I28: 500400 | J28: IRAQ | K28: N | L28: MYR | N28: 697224.8 | P28: 1237194.3 | Q28: 1282880.7 | R28: 651538.37
D29: EXIM | F29: 138901 | I29: 500401 | J29: SEYCHELLES | L29: MYR | N29: 15268958 | P29: 0 | Q29: 0 | R29: 15268958
D30: EXIM | F30: 138901 | I30: 500401 | J30: SEYCHELLES | K30: N | L30: MYR | N30: 4832809.2 | P30: 4984887.8 | Q30: 5369552.7 | R30: 4448144.2
D31: EXIM | F31: 138901 | I31: 500470 | J31: MOF LAO | L31: MYR | N31: 24792892 | P31: 0 | Q31: 0 | R31: 24792892
D32: EXIM | F32: 138901 | I32: 500470 | J32: MOF LAO | K32: N | L32: MYR | N32: 62970920 | P32: 76239833 | Q32: 77919270 | R32: 61291483
D33: EXIM | F33: 138901 | I33: 500512 | J33: AL-MANARA | L33: MYR | N33: 88715176 | P33: 0 | Q33: 0 | R33: 88715176
D34: EXIM | F34: 138901 | I34: 500512 | J34: AL-MANARA | K34: N | L34: MYR | N34: 13267749 | P34: 14969300 | Q34: 14268784 | R34: 13968265
D35: EXIM | F35: 138901 | I35: 500515 | J35: SCOMI | L35: MYR | N35: 27628532 | P35: 0 | Q35: 0 | R35: 27628532
D36: EXIM | F36: 138901 | I36: 500515 | J36: SCOMI | K36: N | L36: MYR | N36: 6410009.3 | P36: 9057910.3 | Q36: 9709267.6 | R36: 5758652
D37: EXIM | F37: 138901 | I37: 500522 | J37: VIRTUAL | L37: MYR | N37: -1055236.6 | P37: 0 | Q37: 0 | R37: -1055236.6
D38: EXIM | F38: 138901 | I38: 500522 | J38: VIRTUAL | K38: N | L38: MYR | N38: 7821758 | P38: 7692274.7 | Q38: 7821758 | R38: 7692274.7
D39: EXIM | F39: 138901 | I39: 500538 | J39: MIR | L39: MYR | N39: 9999973.8 | P39: 1925469.7 | Q39: 261316.26 | R39: 11664127
D40: EXIM | F40: 138901 | I40: 500538 | J40: MIR | K40: N | L40: MYR | N40: 1491682.8 | P40: 22724452 | Q40: 22959806 | R40: 1256328.2
D41: EXIM | F41: 138901 | I41: 500546 | J41: FRESH | L41: MYR | N41: 398103.51 | P41: 0 | Q41: 3625.9 | R41: 394477.61
D42: EXIM | F42: 138901 | I42: 500555 | J42: SOLARTIF | L42: MYR | N42: 781992.08 | P42: 0 | Q42: 61256.05 | R42: 720736.03
...

Sheet Debtors Listing (C) Dec2020
A1: Customer Balances as at December 2020
A3: Customer Account Number | B3: Customer Class & Industry | C3: Customer Name | D3: Loan Currency | E3: Opening Principal | F3: Disbursement | G3: Adjustment Capitalization | H3: Forex ( + ) | I3: Repayment | J3: Adjustment Capitalization | K3: Forex ( - ) | L3: Closing Principal | M3: Maturity Date
A5: 500470 | C5: MINISTRY OF FINANCE - LAO PDR | D5: USD | E5: 86084375 | F5: 0 | G5: 0 | H5: 0 | I5: -6600750 | J5: 0 | K5: -1152125 | L5: 78331500 | M5: 45287
A6: 500937 | C6: THE MINISTRY OF FINANCE LAOS 2 | D6: USD | E6: 2.6360943e+08 | F6: 0 | G6: 0 | H6: 0 | I6: 0 | J6: 0 | K6: -3751986.9 | L6: 2.5985744e+08
B7: Active (Cross Border Credit) (Buyer Credit) | E7: 3.496938e+08 | F7: 0 | G7: 0 | H7: 0 | I7: -6600750 | J7: 0 | K7: -4904111.9 | L7: 3.3818894e+08
A9: 500878 | C9: WOK DELIGHTS SDN BHD | D9: MYR | E9: 1128657.3 | F9: 0 | G9: 0 | H9: 0 | I9: -66391.6 | J9: 0 | K9: 0 | L9: 1062265.7
B10: Active (Malaysia Kitchen Fin) | E10: 1128657.3 | F10: 0 | G10: 0 | H10: 0 | I10: -66391.6 | J10: 0 | K10: 0 | L10: 1062265.7
A12: 500629 | C12: FACADE TREATMENT (Term Loan)CBC | D12: MYR | E12: 1022697.2 | F12: 0 | G12: 0 | H12: 0 | I12: -1022697.2 | J12: 0 | K12: 0 | L12: 0 | M12: 41916
B13: Active (Overseas Contract Fi) (Term Loan) | E13: 1022697.2 | F13: 0 | G13: 0 | H13: 0 | I13: -1022697.2 | J13: 0 | K13: 0 | L13: 0
A15: 500679 | C15: BUMI ARMADA CAPITAL OFFSHORE LTD | D15: USD | E15: 1.9848706e+08 | F15: 0 | G15: 0 | H15: 0 | I15: -7544523.2 | J15: 0 | K15: -2739675.2 | L15: 1.8820286e+08 | M15: 43397
A16: 500708 | C16: SAPURAKENCANA TMC SDN BHD (1) | D16: USD | E16: 14952913 | F16: 0 | G16: 0 | H16: 0 | I16: 0 | J16: 0 | K16: -212826.74 | L16: 14740086 | M16: 44282
A17: 500709 | C17: SAPURAKENCANA TMC SDN BHD (2) | D17: USD | E17: 60502318 | F17: 0 | G17: 0 | H17: 0 | I17: 0 | J17: 0 | K17: -861137.28 | L17: 59641180 | M17: 44282
A18: 500749 | C18: ISTANBUL SABIHA GOKCEN ULUSLARARASI | D18: EUR | E18: 187926200 | F18: 0 | G18: 0 | H18: 2313850 | I18: 0 | J18: 0 | K18: 0 | L18: 190240050
B19: Active (Overseas Investment) | E19: 4.6186849e+08 | F19: 0 | G19: 0 | H19: 2313850 | I19: -7544523.2 | J19: 0 | K19: -3813639.2 | L19: 4.5282418e+08
A21: 500271 | C21: MBI Development D.O.O, Bosnia&Herze | D21: EUR | E21: 4939949.2 | F21: 0 | G21: 0 | H21: 57864.22 | I21: -2355404.6 | J21: 0 | K21: 0 | L21: 2642408.8 | M21: 44176
A22: 500590 | C22: MBI Development 2 | D22: EUR | E22: 5851962.6 | F22: 0 | G22: 0 | H22: 72052.55 | I22: 0 | J22: 0 | K22: 0 | L22: 5924015.1 | M22: 44176
A23: 500640 | C23: OM MATERIAL (SARAWAK) SDN BHD | D23: USD | E23: 1.17814e+08 | F23: 0 | G23: 0 | H23: 0 | I23: 0 | J23: 0 | K23: -1676861.8 | L23: 1.1613714e+08 | M23: 44102
A24: 500642 | C24: OM MATERIAL (SARAWAK) 2 | D24: USD | E24: 1.5974035e+08 | F24: 0 | G24: 0 | H24: 0 | I24: 0 | J24: 0 | K24: -2273605 | L24: 1.5746674e+08 | M24: 45013
A25: 500805 | C25: Armada Kraken Pte Ltd (OPF) | D25: USD | E25: 1.289606e+08 | F25: 0 | G25: 0 | H25: 0 | I25: -9893611.9 | J25: 0 | K25: -1756109.9 | L25: 1.1731088e+08
A26: 500807 | C26: Pertama Ferroalloys Sdn Bhd (2) | D26: USD | E26: 73181824 | F26: 0 | G26: 0 | H26: 0 | I26: -23084870 | J26: 0 | K26: -1041606.3 | L26: 49055348
A27: 500808 | C27: Pertama Ferroalloys Sdn Bhd (1) | D27: USD | E27: 45126331 | F27: 0 | G27: 0 | H27: 0 | I27: -14234893 | J27: 0 | K27: -642288.91 | L27: 30249148
A28: 500827 | C28: Pertama Ferroalloys Sdn Bhd (3) | D28: USD | E28: 99073530 | F28: 0 | G28: 0 | H28: 0 | I28: -31252289 | J28: 0 | K28: -1410126.3 | L28: 66411115
A29: 500885 | C29: SUPERBOOM PROJECTS SDN BHD | D29: USD | E29: 81238988 | F29: 0 | G29: 0 | H29: 0 | I29: 0 | J29: 0 | K29: -1156285 | L29: 80082703
A30: 500905 | C30: ZICO HOLDINGS INC (OPF) | D30: SGD | E30: 2347792.1 | F30: 0 | G30: 0 | H30: 0 | I30: -123693.72 | J30: 0 | K30: -5494.4 | L30: 2218604
A31: 500914 | C31: IMPIANA UBUD (LABUAN) CO. LTD. | D31: USD | E31: 89038750 | F31: 0 | G31: 0 | H31: 0 | I31: 0 | J31: 0 | K31: -1267300 | L31: 87771450
A32: 500927 | C32: BRITISH UNIVERSITY VIETNAM | D32: USD | E32: 76684854 | F32: 0 | G32: 0 | H32: 0 | I32: 0 | J32: 0 | K32: -1091465.4 | L32: 75593389
A33: 501031 | C33: YINSON BORONIA PRODUCTION BV | D33: USD | E33: 19914558 | F33: 16651488 | G33: 0 | H33: 0 | I33: 0 | J33: 0 | K33: -463861.51 | L33: 36102185
B34: Active (Overseas Projec Fin) | E34: 9.0391349e+08 | F34: 16651488 | G34: 0 | H34: 129916.77 | I34: -80944763 | J34: 0 | K34: -12785005 | L34: 8.2696513e+08
A36: 500538 | C36: MIR VALVE SDN BHD | D36: USD | E36: 12920455 | F36: 238448.58 | G36: 0 | H36: 0 | I36: -1430593.8 | J36: 0 | K36: -175308.54 | L36: 11553002 | M36: 42115
A37: 500693 | C37: PERUSAHAAN OTOMOBIL NASIONAL (VF) | D37: MYR | E37: 9680523.9 | F37: 4368985.7 | G37: 0 | H37: 0 | I37: -5274136.5 | J37: 0 | K37: 0 | L37: 8775373.1 | M37: 42004
A38: 500724 | C38: OM Material (Sarawak) Sdn Bhd | D38: USD | E38: 74407175 | F38: 5833966.8 | G38: 0 | H38: 0 | I38: -26007957 | J38: 0 | K38: -926851.63 | L38: 53306333 | M38: 42165
A39: 500840 | C39: Pertama Ferroalloys (Trade) | D39: USD | E39: 17034805 | F39: 19504489 | G39: 0 | H39: 0 | I39: -6890100 | J39: 0 | K39: -430517.22 | L39: 29218676
B40: Active (Supplier Credit) (Trade Finance) | E40: =SUM(E36:E39) -> 1.1404296e+08 | F40: 29945890 | G40: 0 | H40: 0 | I40: -39602787 | J40: 0 | K40: -1532677.4 | L40: =SUM(L36:L39) -> 1.0285338e+08
A42: 501000 | C42: Brahim's Overseas Venture Sdn Bhd | D42: MYR | E42: 15467576 | F42: 0 | G42: 0 | H42: 0 | I42: 0 | J42: 0 | K42: 0 | L42: 15467576
B43: Active (Term Loan) | E43: 15467576 | F43: 0 | G43: 0 | H43: 0 | I43: 0 | J43: 0 | K43: 0 | L43: 15467576
A45: 500010 | C45: PT BUMI INTERNATIONAL TANKERS | D45: USD | E45: 11446432 | F45: 0 | G45: 0 | H45: 0 | I45: 0 | J45: 0 | K45: -162918.52 | L45: 11283514 | M45: 40522
A46: 500011 | C46: PT LAYAR SENTOSA | D46: USD | E46: 11620510 | F46: 0 | G46: 0 | H46: 0 | I46: 0 | J46: 0 | K46: -165396.22 | L46: 11455114 | M46: 40522
A47: 500042 | C47: PT EDEN CAPITAL INDONESIA | D47: USD | E47: 12378749 | F47: 0 | G47: 0 | H47: 0 | I47: 0 | J47: 0 | K47: -176188.34 | L47: 12202561 | M47: 39685
A48: 500265 | C48: PT SARI INDAH LESTARI | D48: USD | E48: 72863488 | F48: 0 | G48: 0 | H48: 0 | I48: 0 | J48: 0 | K48: -1037075.4 | L48: 71826412 | M48: 41029
A49: 500274 | C49: HONDAAFUSHI INVESTMENT PVT LTD | D49: USD | E49: 36242972 | F49: 0 | G49: 0 | H49: 0 | I49: 0 | J49: 0 | K49: -515850.88 | L49: 35727121 | M49: 42946
...

Sheet Mora
